/hpcnfs/home/ieo4462/.conda/envs/snakemake/lib/python3.6/site-packages/snakemake/workflow.py:18: FutureWarning: read_table is deprecated, use read_csv instead, passing sep='\t'.
  
/hpcnfs/home/ieo4462/.conda/envs/snakemake/lib/python3.6/site-packages/snakemake/workflow.py:21: FutureWarning: read_table is deprecated, use read_csv instead, passing sep='\t'.
  from snakemake.exceptions import RuleException, CreateRuleException, \
Building DAG of jobs...
Using shell: /bin/bash
Provided cores: 28
Rules claiming more threads will be scaled down.
Job counts:
	count	jobs
	1	fastp_se
	1

[Mon Mar 25 18:59:44 2019]
Job 0: Processing fastq files from fastq/ISC-Pcgf1KO-rep2-lane1.fastq.gz

[Mon Mar 25 19:00:12 2019]
Error in rule fastp_se:
    jobid: 0
    output: fastq/ISC-Pcgf1KO-rep2.se.fastq.gz
    log: 00log/fastp/ISC-Pcgf1KO-rep2.log

RuleException:
CalledProcessError in line 92 of /hpcnfs/data/DP/SnakemakePipelines/RNAseq-snakemake/trim.smk:
Command 'set -euo pipefail;  cat fastq/ISC-Pcgf1KO-rep2-lane1.fastq.gz > fastq/ISC-Pcgf1KO-rep2.se.fastq.tmp.gz
			fastp -A -z 4 			-i fastq/ISC-Pcgf1KO-rep2.se.fastq.tmp.gz 			-o fastq/ISC-Pcgf1KO-rep2.se.fastq.gz 			-w 5 --stdin -t 1 -A -Q -L 2> 00log/fastp/ISC-Pcgf1KO-rep2.log' returned non-zero exit status 127.
  File "/hpcnfs/data/DP/SnakemakePipelines/RNAseq-snakemake/trim.smk", line 92, in __rule_fastp_se
  File "/hpcnfs/home/ieo4462/.conda/envs/snakemake/lib/python3.6/concurrent/futures/thread.py", line 56, in run
exception calling callback for <Future at 0x2b6fa6a54898 state=finished raised RuleException>
Traceback (most recent call last):
  File "/hpcnfs/home/ieo4462/.conda/envs/snakemake/lib/python3.6/site-packages/snakemake/executors.py", line 1408, in run_wrapper
    passed_shadow_dir)
  File "/hpcnfs/data/DP/SnakemakePipelines/RNAseq-snakemake/trim.smk", line 145, in __rule_fastp_se
  File "/hpcnfs/home/ieo4462/.conda/envs/snakemake/lib/python3.6/site-packages/snakemake/shell.py", line 149, in __new__
    raise sp.CalledProcessError(retcode, cmd)
subprocess.CalledProcessError: Command 'set -euo pipefail;  cat fastq/ISC-Pcgf1KO-rep2-lane1.fastq.gz > fastq/ISC-Pcgf1KO-rep2.se.fastq.tmp.gz
			fastp -A -z 4 			-i fastq/ISC-Pcgf1KO-rep2.se.fastq.tmp.gz 			-o fastq/ISC-Pcgf1KO-rep2.se.fastq.gz 			-w 5 --stdin -t 1 -A -Q -L 2> 00log/fastp/ISC-Pcgf1KO-rep2.log' returned non-zero exit status 127.

During handling of the above exception, another exception occurred:

Traceback (most recent call last):
  File "/hpcnfs/home/ieo4462/.conda/envs/snakemake/lib/python3.6/site-packages/snakemake/executors.py", line 356, in _callback
    raise ex
  File "/hpcnfs/home/ieo4462/.conda/envs/snakemake/lib/python3.6/concurrent/futures/thread.py", line 56, in run
    result = self.fn(*self.args, **self.kwargs)
  File "/hpcnfs/home/ieo4462/.conda/envs/snakemake/lib/python3.6/site-packages/snakemake/executors.py", line 1427, in run_wrapper
    show_traceback=True))
snakemake.exceptions.RuleException: CalledProcessError in line 92 of /hpcnfs/data/DP/SnakemakePipelines/RNAseq-snakemake/trim.smk:
Command 'set -euo pipefail;  cat fastq/ISC-Pcgf1KO-rep2-lane1.fastq.gz > fastq/ISC-Pcgf1KO-rep2.se.fastq.tmp.gz
			fastp -A -z 4 			-i fastq/ISC-Pcgf1KO-rep2.se.fastq.tmp.gz 			-o fastq/ISC-Pcgf1KO-rep2.se.fastq.gz 			-w 5 --stdin -t 1 -A -Q -L 2> 00log/fastp/ISC-Pcgf1KO-rep2.log' returned non-zero exit status 127.
  File "/hpcnfs/data/DP/SnakemakePipelines/RNAseq-snakemake/trim.smk", line 92, in __rule_fastp_se

During handling of the above exception, another exception occurred:

Traceback (most recent call last):
  File "/hpcnfs/home/ieo4462/.conda/envs/snakemake/lib/python3.6/shutil.py", line 544, in move
    os.rename(src, real_dst)
FileNotFoundError: [Errno 2] No such file or directory: '/hpcnfs/data/DP/SnakemakePipelines/RNAseq-snakemake/.snakemake/shadow/tmpo138xyjf/00log/fastp/ISC-Pcgf1KO-rep2.log' -> '00log/fastp/ISC-Pcgf1KO-rep2.log'

During handling of the above exception, another exception occurred:

Traceback (most recent call last):
  File "/hpcnfs/home/ieo4462/.conda/envs/snakemake/lib/python3.6/concurrent/futures/_base.py", line 324, in _invoke_callbacks
    callback(self)
  File "/hpcnfs/home/ieo4462/.conda/envs/snakemake/lib/python3.6/site-packages/snakemake/executors.py", line 367, in _callback
    error_callback(job)
  File "/hpcnfs/home/ieo4462/.conda/envs/snakemake/lib/python3.6/site-packages/snakemake/scheduler.py", line 346, in _error
    self._handle_error(job)
  File "/hpcnfs/home/ieo4462/.conda/envs/snakemake/lib/python3.6/site-packages/snakemake/scheduler.py", line 355, in _handle_error
    self.get_executor(job).handle_job_error(job)
  File "/hpcnfs/home/ieo4462/.conda/envs/snakemake/lib/python3.6/site-packages/snakemake/executors.py", line 373, in handle_job_error
    super().handle_job_error(job)
  File "/hpcnfs/home/ieo4462/.conda/envs/snakemake/lib/python3.6/site-packages/snakemake/executors.py", line 157, in handle_job_error
    latency_wait=self.latency_wait)
  File "/hpcnfs/home/ieo4462/.conda/envs/snakemake/lib/python3.6/site-packages/snakemake/jobs.py", line 882, in postprocess
    self.dag.unshadow_output(self, only_log=error)
  File "/hpcnfs/home/ieo4462/.conda/envs/snakemake/lib/python3.6/site-packages/snakemake/dag.py", line 429, in unshadow_output
    shutil.move(shadow_output, real_output)
  File "/hpcnfs/home/ieo4462/.conda/envs/snakemake/lib/python3.6/shutil.py", line 558, in move
    copy_function(src, real_dst)
  File "/hpcnfs/home/ieo4462/.conda/envs/snakemake/lib/python3.6/shutil.py", line 257, in copy2
    copyfile(src, dst, follow_symlinks=follow_symlinks)
  File "/hpcnfs/home/ieo4462/.conda/envs/snakemake/lib/python3.6/shutil.py", line 120, in copyfile
    with open(src, 'rb') as fsrc:
FileNotFoundError: [Errno 2] No such file or directory: '/hpcnfs/data/DP/SnakemakePipelines/RNAseq-snakemake/.snakemake/shadow/tmpo138xyjf/00log/fastp/ISC-Pcgf1KO-rep2.log'
Will exit after finishing currently running jobs.
